Workbook

Sheet Assumptions
A1: Assumption | B1: Value
A2: Interest Rate | B2: 0.065
A3: Down Payment $ | B3: 20000
A4: Loan Term Years | B4: 30
A5: Property Tax Rate | B5: 0.012
A6: Insurance $/mo | B6: 150
A7: Utilities $/mo | B7: 250
A8: Internet $/mo | B8: 60

Sheet Listings
A1: Address | B1: Town | C1: Listing URL | D1: Price | E1: HOA/mo | F1: Beds | G1: Baths | H1: Sq Ft | I1: In-Unit Laundry | J1: Parking | K1: Down Payment $ | L1: Loan Amount | M1: Monthly Mortgage | N1: Property Tax/mo | O1: Insurance/mo | P1: Utilities+Internet | Q1: Total Monthly Cost | R1: Area Rental Price (Roommate) | S1: Net Monthly Cost | T1: Drive to MBTA (min) | U1: Drive to Seaport (min) | V1: Drive to Google (min) | W1: Rating Score | X1: Rating
A2: 60 Bryon Rd #1, Chestnut Hill, MA 02467 | B2: Newton | C2: https://www.redfin.com/MA/Chestnut-Hill/60-Bryon-Rd-02467/unit-1/home/9204335 | D2: 338399 | E2: 358 | F2: 2 | G2: 1 | H2: 786 | I2: No | J2: 1 space | K2: =Assumptions!B3 | L2: =D2-K2 | M2: =-PMT(Assumptions!B2/12,Assumptions!B4*12,L2) | N2: =D2*Assumptions!B5/12 | O2: =Assumptions!B6 | P2: =Assumptions!B7+Assumptions!B8 | Q2: =M2+E2+N2+O2+P2 | R2: 1430 | S2: =Q2-R2 | T2: 6.2 | U2: 23.2 | V2: 21.7 | W2: 2.45 | X2: Green
A3: 212-A Quincy Shore Dr, Quincy, MA 02171 | B3: Quincy | C3: https://www.redfin.com/MA/Quincy/212-Quincy-Shore-Dr-02171/home/9009303 | D3: 499900 | E3: 0 | F3: 2 | G3: 1 | H3: 864 | I3: No | J3: 0 spaces | K3: =Assumptions!B3 | L3: =D3-K3 | M3: =-PMT(Assumptions!B2/12,Assumptions!B4*12,L3) | N3: =D3*Assumptions!B5/12 | O3: =Assumptions!B6 | P3: =Assumptions!B7+Assumptions!B8 | Q3: =M3+E3+N3+O3+P3 | R3: 1170 | S3: =Q3-R3 | T3: 5 | U3: 12.6 | V3: 16.7 | W3: 2.4 | X3: Green
A4: 975 Washington Streeet, Newton, MA 02460 | B4: Newton | C4: https://www.redfin.com/MA/Newton/975-Washington-St-02460/home/199915977 | D4: 5 | E4: 0 | I4: No | J4: Unknown | K4: =Assumptions!B3 | L4: =D4-K4 | M4: =-PMT(Assumptions!B2/12,Assumptions!B4*12,L4) | N4: =D4*Assumptions!B5/12 | O4: =Assumptions!B6 | P4: =Assumptions!B7+Assumptions!B8 | Q4: =M4+E4+N4+O4+P4 | R4: 0 | S4: =Q4-R4 | T4: 6.1 | U4: 16.7 | V4: 17.3 | W4: 2.4 | X4: Green
A5: 7 Cypress Rd #703, Brighton, MA 02135 | B5: Watertown | C5: https://www.redfin.com/MA/Brighton/7-Cypress-Rd-02135/unit-703/home/9016137 | D5: 448000 | E5: 315 | F5: 2 | G5: 1 | H5: 576 | I5: No | J5: 1 space | K5: =Assumptions!B3 | L5: =D5-K5 | M5: =-PMT(Assumptions!B2/12,Assumptions!B4*12,L5) | N5: =D5*Assumptions!B5/12 | O5: =Assumptions!B6 | P5: =Assumptions!B7+Assumptions!B8 | Q5: =M5+E5+N5+O5+P5 | R5: 1365 | S5: =Q5-R5 | T5: 3.1 | U5: 13.2 | V5: 12.8 | W5: 2.4 | X5: Green
A6: 88 Gordon St #305, Brighton, MA 02135 | B6: Brighton | C6: https://www.redfin.com/MA/Brighton/88-Gordon-St-02135/unit-305/home/9012102 | D6: 299000 | E6: 292 | F6: 1 | G6: 1 | H6: 283 | I6: No | J6: 0 spaces | K6: =Assumptions!B3 | L6: =D6-K6 | M6: =-PMT(Assumptions!B2/12,Assumptions!B4*12,L6) | N6: =D6*Assumptions!B5/12 | O6: =Assumptions!B6 | P6: =Assumptions!B7+Assumptions!B8 | Q6: =M6+E6+N6+O6+P6 | R6: 0 | S6: =Q6-R6 | T6: 3.1 | U6: 12.6 | V6: 12.2 | W6: 2.4 | X6: Green
A7: 198 Allston St #3, Brighton, MA 02134 | B7: Brighton | C7: https://www.redfin.com/MA/Brighton/198-Allston-St-02135/unit-3/home/9013031 | D7: 270000 | E7: 295 | F7: 1 | G7: 1 | H7: 318 | I7: No | J7: 0 spaces | K7: =Assumptions!B3 | L7: =D7-K7 | M7: =-PMT(Assumptions!B2/12,Assumptions!B4*12,L7) | N7: =D7*Assumptions!B5/12 | O7: =Assumptions!B6 | P7: =Assumptions!B7+Assumptions!B8 | Q7: =M7+E7+N7+O7+P7 | R7: 0 | S7: =Q7-R7 | T7: 0.8 | U7: 12.4 | V7: 12 | W7: 2.4 | X7: Green
A8: 0 Gordon Rd, Medford, MA 02155 | B8: Medford | C8: https://www.redfin.com/MA/Medford/0-Gordon-Rd-02155/home/187063221 | D8: 369000 | E8: 0 | I8: No | J8: Unknown | K8: =Assumptions!B3 | L8: =D8-K8 | M8: =-PMT(Assumptions!B2/12,Assumptions!B4*12,L8) | N8: =D8*Assumptions!B5/12 | O8: =Assumptions!B6 | P8: =Assumptions!B7+Assumptions!B8 | Q8: =M8+E8+N8+O8+P8 | R8: 0 | S8: =Q8-R8 | T8: 5 | U8: 12.2 | V8: 12.4 | W8: 2.35 | X8: Green
A9: 18 Allerton St, Quincy, MA 02169 | B9: Quincy | C9: https://www.redfin.com/MA/Quincy/18-Allerton-St-02169/home/110011603 | D9: 200000 | E9: 0 | I9: No | J9: Unknown | K9: =Assumptions!B3 | L9: =D9-K9 | M9: =-PMT(Assumptions!B2/12,Assumptions!B4*12,L9) | N9: =D9*Assumptions!B5/12 | O9: =Assumptions!B6 | P9: =Assumptions!B7+Assumptions!B8 | Q9: =M9+E9+N9+O9+P9 | R9: 0 | S9: =Q9-R9 | T9: 8.4 | U9: 23.3 | V9: 27.4 | W9: 2.3 | X9: Green
A10: 461 Washington St #301, Brighton, MA 02135 | B10: Brighton | C10: https://www.redfin.com/MA/Brighton/461-Washington-St-02135/unit-301/home/11503967 | D10: 419900 | E10: 431 | F10: 2 | G10: 1 | H10: 696 | I10: No | J10: 0 spaces | K10: =Assumptions!B3 | L10: =D10-K10 | M10: =-PMT(Assumptions!B2/12,Assumptions!B4*12,L10) | N10: =D10*Assumptions!B5/12 | O10: =Assumptions!B6 | P10: =Assumptions!B7+Assumptions!B8 | Q10: =M10+E10+N10+O10+P10 | R10: 1300 | S10: =Q10-R10 | T10: 2.9 | U10: 14.6 | V10: 14.2 | W10: 2.3 | X10: Green
A11: 10 Scottfield Rd #2, Allston, MA 02134 | B11: Allston | C11: https://www.redfin.com/MA/Allston/10-Scottfield-Rd-02134/unit-2/home/9000250 | D11: 474900 | E11: 408 | F11: 2 | G11: 1 | H11: 746 | I11: No | J11: 0 spaces | K11: =Assumptions!B3 | L11: =D11-K11 | M11: =-PMT(Assumptions!B2/12,Assumptions!B4*12,L11) | N11: =D11*Assumptions!B5/12 | O11: =Assumptions!B6 | P11: =Assumptions!B7+Assumptions!B8 | Q11: =M11+E11+N11+O11+P11 | R11: 1235 | S11: =Q11-R11 | T11: 2 | U11: 12.2 | V11: 11.8 | W11: 2.3 | X11: Green
A12: 8 Avon St #10, Somerville, MA 02143 | B12: Somerville | C12: https://www.redfin.com/MA/Somerville/8-Avon-St-02143/unit-10/home/8759429 | D12: 500000 | E12: 288 | F12: 2 | G12: 1 | H12: 645 | I12: No | J12: 1 space | K12: =Assumptions!B3 | L12: =D12-K12 | M12: =-PMT(Assumptions!B2/12,Assumptions!B4*12,L12) | N12: =D12*Assumptions!B5/12 | O12: =Assumptions!B6 | P12: =Assumptions!B7+Assumptions!B8 | Q12: =M12+E12+N12+O12+P12 | R12: 1495 | S12: =Q12-R12 | T12: 3.4 | U12: 11.9 | V12: 7.6 | W12: 2.3 | X12: Green
A13: 199 Prospect St Unit A1, Cambridge, MA 02139 | B13: Cambridge | C13: https://www.redfin.com/MA/Cambridge/199-Prospect-St-02139/unit-A1/home/110093910 | D13: 399999 | E13: 183 | F13: 0 | G13: 1 | H13: 389 | I13: No | J13: 0 spaces | K13: =Assumptions!B3 | L13: =D13-K13 | M13: =-PMT(Assumptions!B2/12,Assumptions!B4*12,L13) | N13: =D13*Assumptions!B5/12 | O13: =Assumptions!B6 | P13: =Assumptions!B7+Assumptions!B8 | Q13: =M13+E13+N13+O13+P13 | R13: 0 | S13: =Q13-R13 | T13: 2.4 | U13: 11.2 | V13: 4.1 | W13: 2.3 | X13: Yellow
A14: 186 Lexington St #8, Watertown, MA 02472 | B14: Watertown | C14: https://www.redfin.com/MA/Watertown/186-Lexington-St-02472/unit-8/home/11690422 | D14: 394900 | E14: 350 | F14: 2 | G14: 1 | H14: 600 | I14: No | J14: 1 space | K14: =Assumptions!B3 | L14: =D14-K14 | M14: =-PMT(Assumptions!B2/12,Assumptions!B4*12,L14) | N14: =D14*Assumptions!B5/12 | O14: =Assumptions!B6 | P14: =Assumptions!B7+Assumptions!B8 | Q14: =M14+E14+N14+O14+P14 | R14: 1365 | S14: =Q14-R14 | T14: 12.1 | U14: 18.5 | V14: 17.2 | W14: 2.25 | X14: Yellow
A15: 194 Lexington St #1, Watertown, MA 02472 | B15: Watertown | C15: https://www.redfin.com/MA/Watertown/194-Lexington-St-02472/unit-1/home/11690433 | D15: 375000 | E15: 350 | F15: 2 | G15: 1 | H15: 600 | I15: No | J15: 1 space | K15: =Assumptions!B3 | L15: =D15-K15 | M15: =-PMT(Assumptions!B2/12,Assumptions!B4*12,L15) | N15: =D15*Assumptions!B5/12 | O15: =Assumptions!B6 | P15: =Assumptions!B7+Assumptions!B8 | Q15: =M15+E15+N15+O15+P15 | R15: 1365 | S15: =Q15-R15 | T15: 12.4 | U15: 18.9 | V15: 17 | W15: 2.25 | X15: Yellow
A16: 133 Warren St #3, Watertown, MA 02472 | B16: Watertown | C16: https://www.redfin.com/MA/Watertown/133-Warren-St-02472/unit-3/home/11690534 | D16: 375000 | E16: 350 | F16: 2 | G16: 1 | H16: 600 | I16: No | J16: 2 spaces | K16: =Assumptions!B3 | L16: =D16-K16 | M16: =-PMT(Assumptions!B2/12,Assumptions!B4*12,L16) | N16: =D16*Assumptions!B5/12 | O16: =Assumptions!B6 | P16: =Assumptions!B7+Assumptions!B8 | Q16: =M16+E16+N16+O16+P16 | R16: 1365 | S16: =Q16-R16 | T16: 12.3 | U16: 18.7 | V16: 17.3 | W16: 2.25 | X16: Yellow
A17: 38 Carey Ave #3, Watertown, MA 02472 | B17: Watertown | C17: https://www.redfin.com/MA/Watertown/38-Carey-Ave-02472/unit-3/home/11690323 | D17: 374899 | E17: 350 | F17: 2 | G17: 1 | H17: 600 | I17: No | J17: 1 space | K17: =Assumptions!B3 | L17: =D17-K17 | M17: =-PMT(Assumptions!B2/12,Assumptions!B4*12,L17) | N17: =D17*Assumptions!B5/12 | O17: =Assumptions!B6 | P17: =Assumptions!B7+Assumptions!B8 | Q17: =M17+E17+N17+O17+P17 | R17: 1365 | S17: =Q17-R17 | T17: 12.6 | U17: 19.1 | V17: 17.2 | W17: 2.25 | X17: Yellow
A18: 59 Terne Rd, Quincy, MA 02169 | B18: Quincy | C18: https://www.redfin.com/MA/Quincy/59-Terne-Rd-02169/home/11828578 | D18: 499900 | E18: 0 | F18: 3 | G18: 2 | H18: 1450 | I18: No | J18: 1 space | K18: =Assumptions!B3 | L18: =D18-K18 | M18: =-PMT(Assumptions!B2/12,Assumptions!B4*12,L18) | N18: =D18*Assumptions!B5/12 | O18: =Assumptions!B6 | P18: =Assumptions!B7+Assumptions!B8 | Q18: =M18+E18+N18+O18+P18 | R18: 1170 | S18: =Q18-R18 | T18: 5.8 | U18: 20.7 | V18: 24.8 | W18: 2.25 | X18: Yellow
A19: 1564 Commonwealth Ave #3, Brighton, MA 02135 | B19: Brighton | C19: https://www.redfin.com/MA/Brighton/1564-Commonwealth-Ave-02135/unit-3/home/9017145 | D19: 315000 | E19: 369 | F19: 0 | G19: 1 | H19: 306 | I19: No | J19: 0 spaces | K19: =Assumptions!B3 | L19: =D19-K19 | M19: =-PMT(Assumptions!B2/12,Assumptions!B4*12,L19) | N19: =D19*Assumptions!B5/12 | O19: =Assumptions!B6 | P19: =Assumptions!B7+Assumptions!B8 | Q19: =M19+E19+N19+O19+P19 | R19: 0 | S19: =Q19-R19 | T19: 2 | U19: 13.5 | V19: 13.1 | W19: 2.2 | X19: Yellow
A20: 45 Gordon St #4, Allston, MA 02134 | B20: Allston | C20: https://www.redfin.com/MA/Allston/45-Gordon-St-02134/unit-4/home/8999903 | D20: 489000 | E20: 350 | F20: 2 | G20: 1 | H20: 675 | I20: No | J20: 0 spaces | K20: =Assumptions!B3 | L20: =D20-K20 | M20: =-PMT(Assumptions!B2/12,Assumptions!B4*12,L20) | N20: =D20*Assumptions!B5/12 | O20: =Assumptions!B6 | P20: =Assumptions!B7+Assumptions!B8 | Q20: =M20+E20+N20+O20+P20 | R20: 1235 | S20: =Q20-R20 | T20: 3 | U20: 11.3 | V20: 10.9 | W20: 2.2 | X20: Yellow
A21: 69 Park Dr #10, Boston, MA 02215 | B21: Brookline | C21: https://www.redfin.com/MA/Boston/69-Park-Dr-02215/unit-10/home/9274080 | D21: 360000 | E21: 381 | F21: 0 | G21: 1 | H21: 320 | I21: No | J21: 0 spaces | K21: =Assumptions!B3 | L21: =D21-K21 | M21: =-PMT(Assumptions!B2/12,Assumptions!B4*12,L21) | N21: =D21*Assumptions!B5/12 | O21: =Assumptions!B6 | P21: =Assumptions!B7+Assumptions!B8 | Q21: =M21+E21+N21+O21+P21 | R21: 0 | S21: =Q21-R21 | T21: 1.7 | U21: 11.2 | V21: 9 | W21: 2.2 | X21: Yellow
A22: 7 Mortimer Pl #2, Somerville, MA 02145 | B22: Somerville | C22: https://www.redfin.com/MA/Somerville/7-Mortimer-Pl-02145/unit-2/home/12389682 | D22: 320000 | E22: 366 | F22: 0 | G22: 1 | H22: 429 | I22: No | J22: 1 space | K22: =Assumptions!B3 | L22: =D22-K22 | M22: =-PMT(Assumptions!B2/12,Assumptions!B4*12,L22) | N22: =D22*Assumptions!B5/12 | O22: =Assumptions!B6 | P22: =Assumptions!B7+Assumptions!B8 | Q22: =M22+E22+N22+O22+P22 | R22: 0 | S22: =Q22-R22 | T22: 1.6 | U22: 10.5 | V22: 7.1 | W22: 2.2 | X22: Yellow
A23: 195 Thomas Burgin Pkwy #301, Quincy, MA 02169 | B23: Quincy | C23: https://www.redfin.com/MA/Quincy/195-Thomas-Burgin-Pkwy-02169/unit-301/home/8931809 | D23: 250000 | E23: 393 | F23: 1 | G23: 1 | H23: 447 | I23: No | J23: 0 spaces | K23: =Assumptions!B3 | L23: =D23-K23 | M23: =-PMT(Assumptions!B2/12,Assumptions!B4*12,L23) | N23: =D23*Assumptions!B5/12 | O23: =Assumptions!B6 | P23: =Assumptions!B7+Assumptions!B8 | Q23: =M23+E23+N23+O23+P23 | R23: 0 | S23: =Q23-R23 | T23: 2.2 | U23: 17.6 | V23: 21.7 | W23: 2.15 | X23: Yellow
A24: 195 Thomas Burgin Pkwy #212, Quincy, MA 02169 | B24: Quincy | C24: https://www.redfin.com/MA/Quincy/195-Thomas-Burgin-Pkwy-02169/unit-212/home/8931803 | D24: 249900 | E24: 344 | F24: 0 | G24: 1 | H24: 355 | I24: No | J24: 0 spaces | K24: =Assumptions!B3 | L24: =D24-K24 | M24: =-PMT(Assumptions!B2/12,Assumptions!B4*12,L24) | N24: =D24*Assumptions!B5/12 | O24: =Assumptions!B6 | P24: =Assumptions!B7+Assumptions!B8 | Q24: =M24+E24+N24+O24+P24 | R24: 0 | S24: =Q24-R24 | T24: 2.2 | U24: 17.6 | V24: 21.7 | W24: 2.15 | X24: Yellow
A25: 10 Naviens Ln #1, Waltham, MA 02453 | B25: Waltham | C25: https://www.redfin.com/MA/Waltham/10-Naviens-Ln-02453/unit-1/home/76478882 | D25: 499900 | E25: 134 | F25: 2 | G25: 1 | H25: 1008 | I25: No | J25: 2 spaces | K25: =Assumptions!B3 | L25: =D25-K25 | M25: =-PMT(Assumptions!B2/12,Assumptions!B4*12,L25) | N25: =D25*Assumptions!B5/12 | O25: =Assumptions!B6 | P25: =Assumptions!B7+Assumptions!B8 | Q25: =M25+E25+N25+O25+P25 | R25: 1235 | S25: =Q25-R25 | T25: 10.9 | U25: 19.2 | V25: 19.7 | W25: 2.15 | X25: Yellow
A26: 66 Bryon Rd #2, Chestnut Hill, MA 02467 | B26: Newton | C26: https://www.redfin.com/MA/Chestnut-Hill/66-Bryon-Rd-02467/unit-2/home/9204203 | D26: 385000 | E26: 422 | F26: 2 | G26: 1 | H26: 780 | I26: No | J26: 2 spaces | K26: =Assumptions!B3 | L26: =D26-K26 | M26: =-PMT(Assumptions!B2/12,Assumptions!B4*12,L26) | N26: =D26*Assumptions!B5/12 | O26: =Assumptions!B6 | P26: =Assumptions!B7+Assumptions!B8 | Q26: =M26+E26+N26+O26+P26 | R26: 1430 | S26: =Q26-R26 | T26: 5.9 | U26: 22.9 | V26: 21.4 | W26: 2.15 | X26: Yellow
A27: 5 Braemore Rd #10, Brighton, MA 02135 | B27: Brighton | C27: https://www.redfin.com/MA/Brighton/5-Braemore-Rd-02135/unit-10/home/9308549 | D27: 315000 | E27: 352 | F27: 1 | G27: 1 | H27: 385 | I27: No | J27: 0 spaces | K27: =Assumptions!B3 | L27: =D27-K27 | M27: =-PMT(Assumptions!B2/12,Assumptions!B4*12,L27) | N27: =D27*Assumptions!B5/12 | O27: =Assumptions!B6 | P27: =Assumptions!B7+Assumptions!B8 | Q27: =M27+E27+N27+O27+P27 | R27: 0 | S27: =Q27-R27 | T27: 1.7 | U27: 15.9 | V27: 14.1 | W27: 2.15 | X27: Yellow
A28: 64 Bryon Rd #1, Chestnut Hill, MA 02467 | B28: Newton | C28: https://www.redfin.com/MA/Chestnut-Hill/64-Bryon-Rd-02467/unit-1/home/9204182 | D28: 399000 | E28: 422 | F28: 2 | G28: 1 | H28: 780 | I28: No | J28: 2 spaces | K28: =Assumptions!B3 | L28: =D28-K28 | M28: =-PMT(Assumptions!B2/12,Assumptions!B4*12,L28) | N28: =D28*Assumptions!B5/12 | O28: =Assumptions!B6 | P28: =Assumptions!B7+Assumptions!B8 | Q28: =M28+E28+N28+O28+P28 | R28: 1430 | S28: =Q28-R28 | T28: 5.8 | U28: 22.9 | V28: 21.4 | W28: 2.15 | X28: Yellow
A29: 1641 Commonwealth Ave #16, Brighton, MA 02135 | B29: Brighton | C29: https://www.redfin.com/MA/Brighton/1641-Commonwealth-Ave-02135/unit-16/home/9002891 | D29: 349000 | E29: 399 | F29: 1 | G29: 1 | H29: 407 | I29: No | J29: 0 spaces | K29: =Assumptions!B3 | L29: =D29-K29 | M29: =-PMT(Assumptions!B2/12,Assumptions!B4*12,L29) | N29: =D29*Assumptions!B5/12 | O29: =Assumptions!B6 | P29: =Assumptions!B7+Assumptions!B8 | Q29: =M29+E29+N29+O29+P29 | R29: 0 | S29: =Q29-R29 | T29: 0.4 | U29: 15 | V29: 14.6 | W29: 2.1 | X29: Yellow
A30: 239 Kelton St #41, Allston, MA 02134 | B30: Allston | C30: https://www.redfin.com/MA/Allston/239-Kelton-St-02134/unit-41/home/9001010 | D30: 475000 | E30: 497 | F30: 2 | G30: 1 | H30: 690 | I30: No | J30: 0 spaces | K30: =Assumptions!B3 | L30: =D30-K30 | M30: =-PMT(Assumptions!B2/12,Assumptions!B4*12,L30) | N30: =D30*Assumptions!B5/12 | O30: =Assumptions!B6 | P30: =Assumptions!B7+Assumptions!B8 | Q30: =M30+E30+N30+O30+P30 | R30: 1235 | S30: =Q30-R30 | T30: 2.6 | U30: 12.9 | V30: 12.5 | W30: 2.1 | X30: Yellow
A31: 466 Commonwealth Ave #305, Boston, MA 02215 | B31: Brookline | C31: https://www.redfin.com/MA/Boston/466-Commonwealth-Ave-02215/unit-305/home/9269210 | D31: 489000 | E31: 314 | F31: 0 | G31: 1 | H31: 346 | I31: No | J31: 0 spaces | K31: =Assumptions!B3 | L31: =D31-K31 | M31: =-PMT(Assumptions!B2/12,Assumptions!B4*12,L31) | N31: =D31*Assumptions!B5/12 | O31: =Assumptions!B6 | P31: =Assumptions!B7+Assumptions!B8 | Q31: =M31+E31+N31+O31+P31 | R31: 0 | S31: =Q31-R31 | T31: 1.3 | U31: 11.2 | V31: 7.7 | W31: 2.1 | X31: Yellow
A32: 64 Queensberry St #114, Boston, MA 02215 | B32: Brookline | C32: https://www.redfin.com/MA/Boston/64-Queensberry-St-02215/unit-114/home/9241481 | D32: 425000 | E32: 395 | F32: 0 | G32: 1 | H32: 390 | I32: No | J32: 0 spaces | K32: =Assumptions!B3 | L32: =D32-K32 | M32: =-PMT(Assumptions!B2/12,Assumptions!B4*12,L32) | N32: =D32*Assumptions!B5/12 | O32: =Assumptions!B6 | P32: =Assumptions!B7+Assumptions!B8 | Q32: =M32+E32+N32+O32+P32 | R32: 0 | S32: =Q32-R32 | T32: 1.3 | U32: 11.9 | V32: 9.1 | W32: 2.1 | X32: Yellow
A33: 32 Almont St Unit 32-1, Medford, MA 02155 | B33: Medford | C33: https://www.redfin.com/MA/Medford/32-Almont-St-02155/unit-32-1/home/11802621 | D33: 330000 | E33: 291 | F33: 1 | G33: 1 | H33: 528 | I33: No | J33: 0 spaces | K33: =Assumptions!B3 | L33: =D33-K33 | M33: =-PMT(Assumptions!B2/12,Assumptions!B4*12,L33) | N33: =D33*Assumptions!B5/12 | O33: =Assumptions!B6 | P33: =Assumptions!B7+Assumptions!B8 | Q33: =M33+E33+N33+O33+P33 | R33: 0 | S33: =Q33-R33 | T33: 3.4 | U33: 11.4 | V33: 11.2 | W33: 2.1 | X33: Yellow
A34: 84 Grant St #12, Somerville, MA 02145 | B34: Somerville | C34: https://www.redfin.com/MA/Somerville/84-Grant-St-02145/unit-12/home/8758283 | D34: 395000 | E34: 338 | F34: 1 | G34: 1 | H34: 640 | I34: No | J34: 1 space | K34: =Assumptions!B3 | L34: =D34-K34 | M34: =-PMT(Assumptions!B2/12,Assumptions!B4*12,L34) | N34: =D34*Assumptions!B5/12 | O34: =Assumptions!B6 | P34: =Assumptions!B7+Assumptions!B8 | Q34: =M34+E34+N34+O34+P34 | R34: 0 | S34: =Q34-R34 | T34: 3.2 | U34: 8.2 | V34: 6.8 | W34: 2.1 | X34: Yellow
A35: 500 Salem St #307, Medford, MA 02155 | B35: Medford | C35: https://www.redfin.com/MA/Medford/500-Salem-St-02155/unit-307/home/11784227 | D35: 549000 | E35: 332 | F35: 2 | G35: 2 | H35: 1086 | I35: No | J35: 2 spaces | K35: =Assumptions!B3 | L35: =D35-K35 | M35: =-PMT(Assumptions!B2/12,Assumptions!B4*12,L35) | N35: =D35*Assumptions!B5/12 | O35: =Assumptions!B6 | P35: =Assumptions!B7+Assumptions!B8 | Q35: =M35+E35+N35+O35+P35 | R35: 1235 | S35: =Q35-R35 | T35: 2.2 | U35: 11.6 | V35: 10.2 | W35: 2.1 | X35: Yellow
A36: 872 Massachusetts Ave #303, Cambridge, MA 02139 | B36: Cambridge | C36: https://www.redfin.com/MA/Cambridge/872-Massachusetts-Ave-02139/unit-303/home/136730647 | D36: 598000 | E36: 0 | F36: 1 | G36: 1.5 | H36: 750 | I36: No | J36: 1 space | K36: =Assumptions!B3 | L36: =D36-K36 | M36: =-PMT(Assumptions!B2/12,Assumptions!B4*12,L36) | N36: =D36*Assumptions!B5/12 | O36: =Assumptions!B6 | P36: =Assumptions!B7+Assumptions!B8 | Q36: =M36+E36+N36+O36+P36 | R36: 0 | S36: =Q36-R36 | T36: 1.2 | U36: 12.4 | V36: 5.8 | W36: 2.05 | X36: Yellow
A37: 32 Sidlaw #6, Brighton, MA 02135 | B37: Brighton | C37: https://www.redfin.com/MA/Brighton/32-Sidlaw-Rd-02135/unit-6/home/9006968 | D37: 335000 | E37: 332 | F37: 0 | G37: 1 | H37: 346 | I37: No | J37: 0 spaces | K37: =Assumptions!B3 | L37: =D37-K37 | M37: =-PMT(Assumptions!B2/12,Assumptions!B4*12,L37) | N37: =D37*Assumptions!B5/12 | O37: =Assumptions!B6 | P37: =Assumptions!B7+Assumptions!B8 | Q37: =M37+E37+N37+O37+P37 | R37: 0 | S37: =Q37-R37 | T37: 1.2 | U37: 16.1 | V37: 14.5 | W37: 2.05 | X37: Yellow
A38: 88 Gordon St #304, Brighton, MA 02135 | B38: Brighton | C38: https://www.redfin.com/MA/Brighton/88-Gordon-St-02135/unit-304/home/9226535 | D38: 399000 | E38: 436 | F38: 1 | G38: 1 | H38: 533 | I38: No | J38: 1 space | K38: =Assumptions!B3 | L38: =D38-K38 | M38: =-PMT(Assumptions!B2/12,Assumptions!B4*12,L38) | N38: =D38*Assumptions!B5/12 | O38: =Assumptions!B6 | P38: =Assumptions!B7+Assumptions!B8 | Q38: =M38+E38+N38+O38+P38 | R38: 0 | S38: =Q38-R38 | T38: 3.1 | U38: 12.6 | V38: 12.2 | W38: 2 | X38: Yellow
A39: 15 Commonwealth Ct #10, Brighton, MA 02135 | B39: Brighton | C39: https://www.redfin.com/MA/Brighton/15-Commonwealth-Ct-02135/unit-10/home/9014600 | D39: 379900 | E39: 500 | F39: 1 | G39: 1 | H39: 688 | I39: No | J39: 1 space | K39: =Assumptions!B3 | L39: =D39-K39 | M39: =-PMT(Assumptions!B2/12,Assumptions!B4*12,L39) | N39: =D39*Assumptions!B5/12 | O39: =Assumptions!B6 | P39: =Assumptions!B7+Assumptions!B8 | Q39: =M39+E39+N39+O39+P39 | R39: 0 | S39: =Q39-R39 | T39: 1.2 | U39: 12.8 | V39: 12.4 | W39: 2 | X39: Yellow
A40: 1691 Commonwealth Ave #31, Brighton, MA 02135 | B40: Brighton | C40: https://www.redfin.com/MA/Brighton/1691-Commonwealth-Ave-02135/unit-31/home/9020583 | D40: 414900 | E40: 360 | F40: 1 | G40: 1 | H40: 520 | I40: No | J40: 0 spaces | K40: =Assumptions!B3 | L40: =D40-K40 | M40: =-PMT(Assumptions!B2/12,Assumptions!B4*12,L40) | N40: =D40*Assumptions!B5/12 | O40: =Assumptions!B6 | P40: =Assumptions!B7+Assumptions!B8 | Q40: =M40+E40+N40+O40+P40 | R40: 0 | S40: =Q40-R40 | T40: 1.6 | U40: 14.9 | V40: 14.5 | W40: 2 | X40: Yellow
...
