Workbook

Sheet Assumptions
A1: Assumption | B1: Value
A2: Interest Rate | B2: 0.065
A3: Down Payment $ | B3: 20000
A4: Loan Term Years | B4: 30
A5: Property Tax Rate | B5: 0.012
A6: Insurance $/mo | B6: 150
A7: Utilities $/mo | B7: 250
A8: Internet $/mo | B8: 60

Sheet Listings
A1: Address | B1: Town | C1: Listing URL | D1: Listed Date | E1: Price | F1: HOA/mo | G1: Beds | H1: Baths | I1: Sq Ft | J1: In-Unit Laundry | K1: Parking | L1: Down Payment $ | M1: Loan Amount | N1: Monthly Mortgage | O1: Property Tax/mo | P1: Insurance/mo | Q1: Utilities+Internet | R1: Total Monthly Cost | S1: Rent per Roommate | T1: Net Monthly Cost | U1: Drive to MBTA (min) | V1: Drive to Seaport (min) | W1: Drive to Google (min) | X1: Rating Score | Y1: Rating
A2: 5 Spofford Rd #17, Allston, MA 02134 | B2: Allston | C2: https://www.redfin.com/MA/Allston/5-Spofford-Rd-02134/unit-17/home/8995633 | D2: 2026-01-06 | E2: 225000 | F2: 198 | G2: 0 | H2: 1 | I2: 246 | J2: No | K2: 0 spaces | L2: =Assumptions!B3 | M2: =E2-L2 | N2: =-PMT(Assumptions!B2/12,Assumptions!B4*12,M2) | O2: =E2*Assumptions!B5/12 | P2: =Assumptions!B6 | Q2: =Assumptions!B7+Assumptions!B8 | R2: =N2+F2+O2+P2+Q2 | S2: 0 | T2: =R2-S2*MAX(IFERROR(G2-1,0),0) | U2: 1 | V2: 11.5 | W2: 11.2 | X2: 2.55 | Y2: Green
A3: 40-42 Upham St #1, Malden, MA 02148 | B3: Malden | C3: https://www.redfin.com/MA/Malden/40-Upham-St-02148/unit-1/home/187160997 | D3: 2025-12-11 | E3: 480000 | F3: 0 | G3: 2 | H3: 2 | I3: 933 | J3: No | K3: 1 space | L3: =Assumptions!B3 | M3: =E3-L3 | N3: =-PMT(Assumptions!B2/12,Assumptions!B4*12,M3) | O3: =E3*Assumptions!B5/12 | P3: =Assumptions!B6 | Q3: =Assumptions!B7+Assumptions!B8 | R3: =N3+F3+O3+P3+Q3 | S3: 1202 | T3: =R3-S3*MAX(IFERROR(G3-1,0),0) | U3: 2.3 | V3: 14.1 | W3: 11.6 | X3: 2.55 | Y3: Green
A4: 159 Madison St, Malden, MA 02148 | B4: Malden | C4: https://www.redfin.com/MA/Malden/159-Madison-St-02148/home/11391337 | D4: 2026-04-08 | E4: 524900 | F4: 0 | G4: 2 | H4: 1 | I4: 1091 | J4: No | K4: 2 spaces | L4: =Assumptions!B3 | M4: =E4-L4 | N4: =-PMT(Assumptions!B2/12,Assumptions!B4*12,M4) | O4: =E4*Assumptions!B5/12 | P4: =Assumptions!B6 | Q4: =Assumptions!B7+Assumptions!B8 | R4: =N4+F4+O4+P4+Q4 | S4: 1202 | T4: =R4-S4*MAX(IFERROR(G4-1,0),0) | U4: 2.2 | V4: 12.1 | W4: 10.5 | X4: 2.45 | Y4: Green
A5: 111 Devir #204, Malden, MA 02148 | B5: Malden | C5: https://www.redfin.com/MA/Malden/111-Devir-St-02148/unit-204/home/11388868 | D5: 2026-04-01 | E5: 469000 | F5: 343 | G5: 2 | H5: 1.5 | I5: 936 | J5: No | K5: 1 space | L5: =Assumptions!B3 | M5: =E5-L5 | N5: =-PMT(Assumptions!B2/12,Assumptions!B4*12,M5) | O5: =E5*Assumptions!B5/12 | P5: =Assumptions!B6 | Q5: =Assumptions!B7+Assumptions!B8 | R5: =N5+F5+O5+P5+Q5 | S5: 1202 | T5: =R5-S5*MAX(IFERROR(G5-1,0),0) | U5: 3.2 | V5: 11.1 | W5: 9.7 | X5: 2.45 | Y5: Green
A6: 212-A Quincy Shore Dr, Quincy, MA 02171 | B6: Quincy | C6: https://www.redfin.com/MA/Quincy/212-Quincy-Shore-Dr-02171/home/9009303 | E6: 499900 | F6: 0 | G6: 2 | H6: 1 | I6: 864 | J6: No | K6: 0 spaces | L6: =Assumptions!B3 | M6: =E6-L6 | N6: =-PMT(Assumptions!B2/12,Assumptions!B4*12,M6) | O6: =E6*Assumptions!B5/12 | P6: =Assumptions!B6 | Q6: =Assumptions!B7+Assumptions!B8 | R6: =N6+F6+O6+P6+Q6 | S6: 1170 | T6: =R6-S6*MAX(IFERROR(G6-1,0),0) | U6: 5 | V6: 12.6 | W6: 16.7 | X6: 2.4 | Y6: Green
A7: 198 Allston St #3, Brighton, MA 02134 | B7: Brighton | C7: https://www.redfin.com/MA/Brighton/198-Allston-St-02135/unit-3/home/9013031 | E7: 270000 | F7: 295 | G7: 1 | H7: 1 | I7: 318 | J7: No | K7: 0 spaces | L7: =Assumptions!B3 | M7: =E7-L7 | N7: =-PMT(Assumptions!B2/12,Assumptions!B4*12,M7) | O7: =E7*Assumptions!B5/12 | P7: =Assumptions!B6 | Q7: =Assumptions!B7+Assumptions!B8 | R7: =N7+F7+O7+P7+Q7 | S7: 0 | T7: =R7-S7*MAX(IFERROR(G7-1,0),0) | U7: 0.8 | V7: 12.4 | W7: 12 | X7: 2.4 | Y7: Green
A8: 0 Gordon Rd, Medford, MA 02155 | B8: Medford | C8: https://www.redfin.com/MA/Medford/0-Gordon-Rd-02155/home/187063221 | E8: 369000 | F8: 0 | J8: No | K8: Unknown | L8: =Assumptions!B3 | M8: =E8-L8 | N8: =-PMT(Assumptions!B2/12,Assumptions!B4*12,M8) | O8: =E8*Assumptions!B5/12 | P8: =Assumptions!B6 | Q8: =Assumptions!B7+Assumptions!B8 | R8: =N8+F8+O8+P8+Q8 | S8: 0 | T8: =R8-S8*MAX(IFERROR(G8-1,0),0) | U8: 5 | V8: 12.2 | W8: 12.4 | X8: 2.35 | Y8: Green
A9: 27 Sixth Ave, Quincy, MA 02169 | B9: Quincy | C9: https://www.redfin.com/MA/Quincy/27-6th-Ave-02169/home/8946597 | E9: 499000 | F9: 0 | G9: 3 | H9: 1 | I9: 1134 | J9: No | K9: 0 spaces | L9: =Assumptions!B3 | M9: =E9-L9 | N9: =-PMT(Assumptions!B2/12,Assumptions!B4*12,M9) | O9: =E9*Assumptions!B5/12 | P9: =Assumptions!B6 | Q9: =Assumptions!B7+Assumptions!B8 | R9: =N9+F9+O9+P9+Q9 | S9: 1170 | T9: =R9-S9*MAX(IFERROR(G9-1,0),0) | U9: 4 | V9: 20.1 | W9: 24.2 | X9: 2.35 | Y9: Green
A10: 1 Glenwood St #5, Malden, MA 02148 | B10: Malden | C10: https://www.redfin.com/MA/Malden/1-Glenwood-St-02148/unit-5/home/11429024 | D10: 2026-03-25 | E10: 499000 | F10: 327 | G10: 3 | H10: 2 | I10: 1098 | J10: No | K10: 0 spaces | L10: =Assumptions!B3 | M10: =E10-L10 | N10: =-PMT(Assumptions!B2/12,Assumptions!B4*12,M10) | O10: =E10*Assumptions!B5/12 | P10: =Assumptions!B6 | Q10: =Assumptions!B7+Assumptions!B8 | R10: =N10+F10+O10+P10+Q10 | S10: 1202 | T10: =R10-S10*MAX(IFERROR(G10-1,0),0) | U10: 0.3 | V10: 14.2 | W10: 12.7 | X10: 2.35 | Y10: Green
A11: 217-221 Highland Ave #2, Malden, MA 02148 | B11: Malden | C11: https://www.redfin.com/MA/Malden/217-Highland-Ave-02148/unit-2/home/137151214 | D11: 2025-06-17 | E11: 499800 | F11: 390 | G11: 3 | H11: 1.5 | I11: 1483 | J11: No | K11: 2 spaces | L11: =Assumptions!B3 | M11: =E11-L11 | N11: =-PMT(Assumptions!B2/12,Assumptions!B4*12,M11) | O11: =E11*Assumptions!B5/12 | P11: =Assumptions!B6 | Q11: =Assumptions!B7+Assumptions!B8 | R11: =N11+F11+O11+P11+Q11 | S11: 1202 | T11: =R11-S11*MAX(IFERROR(G11-1,0),0) | U11: 2 | V11: 11.2 | W11: 9.8 | X11: 2.35 | Y11: Green
A12: 18 Allerton St, Quincy, MA 02169 | B12: Quincy | C12: https://www.redfin.com/MA/Quincy/18-Allerton-St-02169/home/110011603 | E12: 200000 | F12: 0 | J12: No | K12: Unknown | L12: =Assumptions!B3 | M12: =E12-L12 | N12: =-PMT(Assumptions!B2/12,Assumptions!B4*12,M12) | O12: =E12*Assumptions!B5/12 | P12: =Assumptions!B6 | Q12: =Assumptions!B7+Assumptions!B8 | R12: =N12+F12+O12+P12+Q12 | S12: 0 | T12: =R12-S12*MAX(IFERROR(G12-1,0),0) | U12: 8.4 | V12: 23.3 | W12: 27.4 | X12: 2.3 | Y12: Green
A13: 10 Scottfield Rd #2, Allston, MA 02134 | B13: Allston | C13: https://www.redfin.com/MA/Allston/10-Scottfield-Rd-02134/unit-2/home/9000250 | E13: 474900 | F13: 408 | G13: 2 | H13: 1 | I13: 746 | J13: No | K13: 0 spaces | L13: =Assumptions!B3 | M13: =E13-L13 | N13: =-PMT(Assumptions!B2/12,Assumptions!B4*12,M13) | O13: =E13*Assumptions!B5/12 | P13: =Assumptions!B6 | Q13: =Assumptions!B7+Assumptions!B8 | R13: =N13+F13+O13+P13+Q13 | S13: 1235 | T13: =R13-S13*MAX(IFERROR(G13-1,0),0) | U13: 2 | V13: 12.2 | W13: 11.8 | X13: 2.3 | Y13: Green
A14: 199 Prospect St Unit A1, Cambridge, MA 02139 | B14: Cambridge | C14: https://www.redfin.com/MA/Cambridge/199-Prospect-St-02139/unit-A1/home/110093910 | E14: 399999 | F14: 183 | G14: 0 | H14: 1 | I14: 389 | J14: No | K14: 0 spaces | L14: =Assumptions!B3 | M14: =E14-L14 | N14: =-PMT(Assumptions!B2/12,Assumptions!B4*12,M14) | O14: =E14*Assumptions!B5/12 | P14: =Assumptions!B6 | Q14: =Assumptions!B7+Assumptions!B8 | R14: =N14+F14+O14+P14+Q14 | S14: 0 | T14: =R14-S14*MAX(IFERROR(G14-1,0),0) | U14: 2.4 | V14: 11.2 | W14: 4.1 | X14: 2.3 | Y14: Yellow
A15: 239 Kelton St #11, Allston, MA 02134 | B15: Allston | C15: https://www.redfin.com/MA/Allston/239-Kelton-St-02134/unit-11/home/9000947 | E15: 465000 | F15: 400 | G15: 2 | H15: 1 | I15: 690 | J15: No | K15: 1 space | L15: =Assumptions!B3 | M15: =E15-L15 | N15: =-PMT(Assumptions!B2/12,Assumptions!B4*12,M15) | O15: =E15*Assumptions!B5/12 | P15: =Assumptions!B6 | Q15: =Assumptions!B7+Assumptions!B8 | R15: =N15+F15+O15+P15+Q15 | S15: 1235 | T15: =R15-S15*MAX(IFERROR(G15-1,0),0) | U15: 2.6 | V15: 12.9 | W15: 12.5 | X15: 2.3 | Y15: Green
A16: 84 Grant St #7, Somerville, MA 02145 | B16: Somerville | C16: https://www.redfin.com/MA/Somerville/84-Grant-St-02145/unit-7/home/11650236 | E16: 469000 | F16: 439 | G16: 2 | H16: 1 | I16: 835 | J16: No | K16: 1 space | L16: =Assumptions!B3 | M16: =E16-L16 | N16: =-PMT(Assumptions!B2/12,Assumptions!B4*12,M16) | O16: =E16*Assumptions!B5/12 | P16: =Assumptions!B6 | Q16: =Assumptions!B7+Assumptions!B8 | R16: =N16+F16+O16+P16+Q16 | S16: 1495 | T16: =R16-S16*MAX(IFERROR(G16-1,0),0) | U16: 3.2 | V16: 8.2 | W16: 6.8 | X16: 2.3 | Y16: Green
A17: 186 Lexington St #8, Watertown, MA 02472 | B17: Watertown | C17: https://www.redfin.com/MA/Watertown/186-Lexington-St-02472/unit-8/home/11690422 | E17: 394900 | F17: 350 | G17: 2 | H17: 1 | I17: 600 | J17: No | K17: 1 space | L17: =Assumptions!B3 | M17: =E17-L17 | N17: =-PMT(Assumptions!B2/12,Assumptions!B4*12,M17) | O17: =E17*Assumptions!B5/12 | P17: =Assumptions!B6 | Q17: =Assumptions!B7+Assumptions!B8 | R17: =N17+F17+O17+P17+Q17 | S17: 1365 | T17: =R17-S17*MAX(IFERROR(G17-1,0),0) | U17: 12.1 | V17: 18.5 | W17: 17.2 | X17: 2.25 | Y17: Yellow
A18: 194 Lexington St #1, Watertown, MA 02472 | B18: Watertown | C18: https://www.redfin.com/MA/Watertown/194-Lexington-St-02472/unit-1/home/11690433 | E18: 375000 | F18: 350 | G18: 2 | H18: 1 | I18: 600 | J18: No | K18: 1 space | L18: =Assumptions!B3 | M18: =E18-L18 | N18: =-PMT(Assumptions!B2/12,Assumptions!B4*12,M18) | O18: =E18*Assumptions!B5/12 | P18: =Assumptions!B6 | Q18: =Assumptions!B7+Assumptions!B8 | R18: =N18+F18+O18+P18+Q18 | S18: 1365 | T18: =R18-S18*MAX(IFERROR(G18-1,0),0) | U18: 12.4 | V18: 18.9 | W18: 17 | X18: 2.25 | Y18: Yellow
A19: 133 Warren St #3, Watertown, MA 02472 | B19: Watertown | C19: https://www.redfin.com/MA/Watertown/133-Warren-St-02472/unit-3/home/11690534 | E19: 375000 | F19: 350 | G19: 2 | H19: 1 | I19: 600 | J19: No | K19: 2 spaces | L19: =Assumptions!B3 | M19: =E19-L19 | N19: =-PMT(Assumptions!B2/12,Assumptions!B4*12,M19) | O19: =E19*Assumptions!B5/12 | P19: =Assumptions!B6 | Q19: =Assumptions!B7+Assumptions!B8 | R19: =N19+F19+O19+P19+Q19 | S19: 1365 | T19: =R19-S19*MAX(IFERROR(G19-1,0),0) | U19: 12.3 | V19: 18.7 | W19: 17.3 | X19: 2.25 | Y19: Yellow
A20: 12 Gaston St, Medford, MA 02155 | B20: Medford | C20: https://www.redfin.com/MA/Medford/12-Gaston-St-02155/home/11778344 | E20: 375000 | F20: 0 | J20: No | K20: Unknown | L20: =Assumptions!B3 | M20: =E20-L20 | N20: =-PMT(Assumptions!B2/12,Assumptions!B4*12,M20) | O20: =E20*Assumptions!B5/12 | P20: =Assumptions!B6 | Q20: =Assumptions!B7+Assumptions!B8 | R20: =N20+F20+O20+P20+Q20 | S20: 0 | T20: =R20-S20*MAX(IFERROR(G20-1,0),0) | U20: 5.4 | V20: 12.3 | W20: 12.5 | X20: 2.25 | Y20: Yellow
A21: 77 Forest St, Watertown, MA 02472 | B21: Watertown | C21: https://www.redfin.com/MA/Watertown/77-Forest-St-02472/home/195635313 | E21: 299500 | F21: 0 | G21: 1 | H21: 1.5 | I21: 1040 | J21: No | K21: 0 spaces | L21: =Assumptions!B3 | M21: =E21-L21 | N21: =-PMT(Assumptions!B2/12,Assumptions!B4*12,M21) | O21: =E21*Assumptions!B5/12 | P21: =Assumptions!B6 | Q21: =Assumptions!B7+Assumptions!B8 | R21: =N21+F21+O21+P21+Q21 | S21: 0 | T21: =R21-S21*MAX(IFERROR(G21-1,0),0) | U21: 10.9 | V21: 17.3 | W21: 17.1 | X21: 2.25 | Y21: Yellow
A22: 69A Strathmore St Unit 69A, Boston, MA 02135 | B22: Brighton | C22: https://www.redfin.com/MA/Boston/69-Strathmore-Rd-02135/unit-69A/home/200893159 | E22: 489000 | F22: 373 | G22: 2 | H22: 1 | I22: 638 | J22: No | K22: 0 spaces | L22: =Assumptions!B3 | M22: =E22-L22 | N22: =-PMT(Assumptions!B2/12,Assumptions!B4*12,M22) | O22: =E22*Assumptions!B5/12 | P22: =Assumptions!B6 | Q22: =Assumptions!B7+Assumptions!B8 | R22: =N22+F22+O22+P22+Q22 | S22: 1300 | T22: =R22-S22*MAX(IFERROR(G22-1,0),0) | U22: 0.6 | V22: 16 | W22: 13.4 | X22: 2.25 | Y22: Yellow
A23: 185 Chestnut Hill Ave #3, Brighton, MA 02135 | B23: Brighton | C23: https://www.redfin.com/MA/Brighton/185-Chestnut-Hill-Ave-02135/unit-3/home/9036757 | E23: 395000 | F23: 442 | G23: 2 | H23: 1 | I23: 623 | J23: No | K23: 0 spaces | L23: =Assumptions!B3 | M23: =E23-L23 | N23: =-PMT(Assumptions!B2/12,Assumptions!B4*12,M23) | O23: =E23*Assumptions!B5/12 | P23: =Assumptions!B6 | Q23: =Assumptions!B7+Assumptions!B8 | R23: =N23+F23+O23+P23+Q23 | S23: 1300 | T23: =R23-S23*MAX(IFERROR(G23-1,0),0) | U23: 2.7 | V23: 15.7 | W23: 15.4 | X23: 2.25 | Y23: Yellow
A24: 82 Medford St #2, Malden, MA 02148 | B24: Malden | C24: https://www.redfin.com/MA/Malden/82-Medford-St-02148/unit-2/home/11431345 | D24: 2026-03-04 | E24: 549990 | F24: 207 | G24: 3 | H24: 1.5 | I24: 1319 | J24: No | K24: 3 spaces | L24: =Assumptions!B3 | M24: =E24-L24 | N24: =-PMT(Assumptions!B2/12,Assumptions!B4*12,M24) | O24: =E24*Assumptions!B5/12 | P24: =Assumptions!B6 | Q24: =Assumptions!B7+Assumptions!B8 | R24: =N24+F24+O24+P24+Q24 | S24: 1202 | T24: =R24-S24*MAX(IFERROR(G24-1,0),0) | U24: 2.3 | V24: 12 | W24: 10.2 | X24: 2.25 | Y24: Yellow
A25: 45 Gordon St #4, Allston, MA 02134 | B25: Allston | C25: https://www.redfin.com/MA/Allston/45-Gordon-St-02134/unit-4/home/8999903 | E25: 489000 | F25: 350 | G25: 2 | H25: 1 | I25: 675 | J25: No | K25: 0 spaces | L25: =Assumptions!B3 | M25: =E25-L25 | N25: =-PMT(Assumptions!B2/12,Assumptions!B4*12,M25) | O25: =E25*Assumptions!B5/12 | P25: =Assumptions!B6 | Q25: =Assumptions!B7+Assumptions!B8 | R25: =N25+F25+O25+P25+Q25 | S25: 1235 | T25: =R25-S25*MAX(IFERROR(G25-1,0),0) | U25: 3 | V25: 11.3 | W25: 10.9 | X25: 2.2 | Y25: Yellow
A26: 12-14 Shannon St #3, Brighton, MA 02135 | B26: Brighton | C26: https://www.redfin.com/MA/Brighton/12-14-Shannon-St-02135/unit-3/home/11838033 | E26: 599000 | F26: 280 | G26: 3 | H26: 1 | I26: 908 | J26: No | K26: 3 spaces | L26: =Assumptions!B3 | M26: =E26-L26 | N26: =-PMT(Assumptions!B2/12,Assumptions!B4*12,M26) | O26: =E26*Assumptions!B5/12 | P26: =Assumptions!B6 | Q26: =Assumptions!B7+Assumptions!B8 | R26: =N26+F26+O26+P26+Q26 | S26: 1300 | T26: =R26-S26*MAX(IFERROR(G26-1,0),0) | U26: 1.9 | V26: 13.6 | W26: 13.2 | X26: 2.2 | Y26: Yellow
A27: 102 Grant Unit B, Somerville, MA 02145 | B27: Somerville | C27: https://www.redfin.com/MA/Somerville/102-Grant-St-02145/unit-B/home/196668060 | E27: 599000 | F27: 200 | G27: 2 | H27: 1 | I27: 1162 | J27: No | K27: 0 spaces | L27: =Assumptions!B3 | M27: =E27-L27 | N27: =-PMT(Assumptions!B2/12,Assumptions!B4*12,M27) | O27: =E27*Assumptions!B5/12 | P27: =Assumptions!B6 | Q27: =Assumptions!B7+Assumptions!B8 | R27: =N27+F27+O27+P27+Q27 | S27: 1495 | T27: =R27-S27*MAX(IFERROR(G27-1,0),0) | U27: 3.7 | V27: 7.9 | W27: 6.5 | X27: 2.2 | Y27: Yellow
A28: 195 Thomas Burgin Pkwy #301, Quincy, MA 02169 | B28: Quincy | C28: https://www.redfin.com/MA/Quincy/195-Thomas-Burgin-Pkwy-02169/unit-301/home/8931809 | E28: 250000 | F28: 393 | G28: 1 | H28: 1 | I28: 447 | J28: No | K28: 0 spaces | L28: =Assumptions!B3 | M28: =E28-L28 | N28: =-PMT(Assumptions!B2/12,Assumptions!B4*12,M28) | O28: =E28*Assumptions!B5/12 | P28: =Assumptions!B6 | Q28: =Assumptions!B7+Assumptions!B8 | R28: =N28+F28+O28+P28+Q28 | S28: 0 | T28: =R28-S28*MAX(IFERROR(G28-1,0),0) | U28: 2.2 | V28: 17.6 | W28: 21.7 | X28: 2.15 | Y28: Yellow
A29: 10 Naviens Ln #1, Waltham, MA 02453 | B29: Waltham | C29: https://www.redfin.com/MA/Waltham/10-Naviens-Ln-02453/unit-1/home/76478882 | E29: 499900 | F29: 134 | G29: 2 | H29: 1 | I29: 1008 | J29: No | K29: 2 spaces | L29: =Assumptions!B3 | M29: =E29-L29 | N29: =-PMT(Assumptions!B2/12,Assumptions!B4*12,M29) | O29: =E29*Assumptions!B5/12 | P29: =Assumptions!B6 | Q29: =Assumptions!B7+Assumptions!B8 | R29: =N29+F29+O29+P29+Q29 | S29: 1235 | T29: =R29-S29*MAX(IFERROR(G29-1,0),0) | U29: 10.9 | V29: 19.2 | W29: 19.7 | X29: 2.15 | Y29: Yellow
A30: 66 Bryon Rd #2, Chestnut Hill, MA 02467 | B30: Newton | C30: https://www.redfin.com/MA/Chestnut-Hill/66-Bryon-Rd-02467/unit-2/home/9204203 | E30: 385000 | F30: 422 | G30: 2 | H30: 1 | I30: 780 | J30: No | K30: 2 spaces | L30: =Assumptions!B3 | M30: =E30-L30 | N30: =-PMT(Assumptions!B2/12,Assumptions!B4*12,M30) | O30: =E30*Assumptions!B5/12 | P30: =Assumptions!B6 | Q30: =Assumptions!B7+Assumptions!B8 | R30: =N30+F30+O30+P30+Q30 | S30: 1430 | T30: =R30-S30*MAX(IFERROR(G30-1,0),0) | U30: 5.9 | V30: 22.9 | W30: 21.4 | X30: 2.15 | Y30: Yellow
A31: 5 Braemore Rd #10, Brighton, MA 02135 | B31: Brighton | C31: https://www.redfin.com/MA/Brighton/5-Braemore-Rd-02135/unit-10/home/9308549 | E31: 315000 | F31: 352 | G31: 1 | H31: 1 | I31: 385 | J31: No | K31: 0 spaces | L31: =Assumptions!B3 | M31: =E31-L31 | N31: =-PMT(Assumptions!B2/12,Assumptions!B4*12,M31) | O31: =E31*Assumptions!B5/12 | P31: =Assumptions!B6 | Q31: =Assumptions!B7+Assumptions!B8 | R31: =N31+F31+O31+P31+Q31 | S31: 0 | T31: =R31-S31*MAX(IFERROR(G31-1,0),0) | U31: 1.7 | V31: 15.9 | W31: 14.1 | X31: 2.15 | Y31: Yellow
A32: 64 Bryon Rd #1, Chestnut Hill, MA 02467 | B32: Newton | C32: https://www.redfin.com/MA/Chestnut-Hill/64-Bryon-Rd-02467/unit-1/home/9204182 | E32: 399000 | F32: 422 | G32: 2 | H32: 1 | I32: 780 | J32: No | K32: 2 spaces | L32: =Assumptions!B3 | M32: =E32-L32 | N32: =-PMT(Assumptions!B2/12,Assumptions!B4*12,M32) | O32: =E32*Assumptions!B5/12 | P32: =Assumptions!B6 | Q32: =Assumptions!B7+Assumptions!B8 | R32: =N32+F32+O32+P32+Q32 | S32: 1430 | T32: =R32-S32*MAX(IFERROR(G32-1,0),0) | U32: 5.8 | V32: 22.9 | W32: 21.4 | X32: 2.15 | Y32: Yellow
A33: 1641 Commonwealth Ave #16, Brighton, MA 02135 | B33: Brighton | C33: https://www.redfin.com/MA/Brighton/1641-Commonwealth-Ave-02135/unit-16/home/9002891 | D33: 2026-04-08 | E33: 349000 | F33: 399 | G33: 1 | H33: 1 | I33: 407 | J33: No | K33: 0 spaces | L33: =Assumptions!B3 | M33: =E33-L33 | N33: =-PMT(Assumptions!B2/12,Assumptions!B4*12,M33) | O33: =E33*Assumptions!B5/12 | P33: =Assumptions!B6 | Q33: =Assumptions!B7+Assumptions!B8 | R33: =N33+F33+O33+P33+Q33 | S33: 0 | T33: =R33-S33*MAX(IFERROR(G33-1,0),0) | U33: 0.4 | V33: 15 | W33: 14.6 | X33: 2.15 | Y33: Yellow
A34: 1568 Commonwealth Ave #12, Brighton, MA 02135 | B34: Brighton | C34: https://www.redfin.com/MA/Brighton/1568-Commonwealth-Ave-02135/unit-12/home/9017105 | D34: 2026-04-09 | E34: 314900 | F34: 369 | G34: 1 | H34: 1 | I34: 306 | J34: No | K34: 0 spaces | L34: =Assumptions!B3 | M34: =E34-L34 | N34: =-PMT(Assumptions!B2/12,Assumptions!B4*12,M34) | O34: =E34*Assumptions!B5/12 | P34: =Assumptions!B6 | Q34: =Assumptions!B7+Assumptions!B8 | R34: =N34+F34+O34+P34+Q34 | S34: 0 | T34: =R34-S34*MAX(IFERROR(G34-1,0),0) | U34: 1.2 | V34: 13.7 | W34: 13.3 | X34: 2.15 | Y34: Yellow
A35: 10 Scottfield Rd #34, Allston, MA 02134 | B35: Allston | C35: https://www.redfin.com/MA/Allston/10-Scottfield-Rd-02134/unit-34/home/9000321 | D35: 2026-04-08 | E35: 499000 | F35: 408 | G35: 2 | H35: 1 | I35: 746 | J35: No | K35: 1 space | L35: =Assumptions!B3 | M35: =E35-L35 | N35: =-PMT(Assumptions!B2/12,Assumptions!B4*12,M35) | O35: =E35*Assumptions!B5/12 | P35: =Assumptions!B6 | Q35: =Assumptions!B7+Assumptions!B8 | R35: =N35+F35+O35+P35+Q35 | S35: 1235 | T35: =R35-S35*MAX(IFERROR(G35-1,0),0) | U35: 2 | V35: 12.2 | W35: 11.8 | X35: 2.15 | Y35: Yellow
A36: 239 Kelton St #41, Allston, MA 02134 | B36: Allston | C36: https://www.redfin.com/MA/Allston/239-Kelton-St-02134/unit-41/home/9001010 | E36: 475000 | F36: 497 | G36: 2 | H36: 1 | I36: 690 | J36: No | K36: 0 spaces | L36: =Assumptions!B3 | M36: =E36-L36 | N36: =-PMT(Assumptions!B2/12,Assumptions!B4*12,M36) | O36: =E36*Assumptions!B5/12 | P36: =Assumptions!B6 | Q36: =Assumptions!B7+Assumptions!B8 | R36: =N36+F36+O36+P36+Q36 | S36: 1235 | T36: =R36-S36*MAX(IFERROR(G36-1,0),0) | U36: 2.6 | V36: 12.9 | W36: 12.5 | X36: 2.1 | Y36: Yellow
A37: 34 Channing St #2, Newton, MA 02458 | B37: Newton | C37: https://www.redfin.com/MA/Newton/34-Channing-St-02458/unit-2/home/196688205 | E37: 598000 | F37: 237 | G37: 3 | H37: 1 | I37: 1387 | J37: No | K37: 1 space | L37: =Assumptions!B3 | M37: =E37-L37 | N37: =-PMT(Assumptions!B2/12,Assumptions!B4*12,M37) | O37: =E37*Assumptions!B5/12 | P37: =Assumptions!B6 | Q37: =Assumptions!B7+Assumptions!B8 | R37: =N37+F37+O37+P37+Q37 | S37: 1430 | T37: =R37-S37*MAX(IFERROR(G37-1,0),0) | U37: 8 | V37: 14.3 | W37: 14.9 | X37: 2.1 | Y37: Yellow
A38: 57 Brighton Ave #6, Allston, MA 02134 | B38: Allston | C38: https://www.redfin.com/MA/Allston/57-Brighton-Ave-02134/unit-6/home/8991939 | E38: 429000 | F38: 0 | G38: 1 | H38: 1 | I38: 620 | J38: No | K38: Unknown | L38: =Assumptions!B3 | M38: =E38-L38 | N38: =-PMT(Assumptions!B2/12,Assumptions!B4*12,M38) | O38: =E38*Assumptions!B5/12 | P38: =Assumptions!B6 | Q38: =Assumptions!B7+Assumptions!B8 | R38: =N38+F38+O38+P38+Q38 | S38: 0 | T38: =R38-S38*MAX(IFERROR(G38-1,0),0) | U38: 2.2 | V38: 10.6 | W38: 10.3 | X38: 2.1 | Y38: Yellow
A39: 297 Main St #3, Medford, MA 02155 | B39: Medford | C39: https://www.redfin.com/MA/Medford/297-Main-St-02155/unit-3/home/11796231 | E39: 368000 | F39: 324 | G39: 1 | H39: 1 | I39: 596 | J39: No | K39: 1 space | L39: =Assumptions!B3 | M39: =E39-L39 | N39: =-PMT(Assumptions!B2/12,Assumptions!B4*12,M39) | O39: =E39*Assumptions!B5/12 | P39: =Assumptions!B6 | Q39: =Assumptions!B7+Assumptions!B8 | R39: =N39+F39+O39+P39+Q39 | S39: 0 | T39: =R39-S39*MAX(IFERROR(G39-1,0),0) | U39: 1.8 | V39: 11 | W39: 9.6 | X39: 2.1 | Y39: Yellow
A40: , Boston, MA 02135 | B40: Brighton | C40: https://www.redfin.com/MA/Brighton/Undisclosed-address-02135/home/9013888 | E40: 469000 | F40: 0 | G40: 1 | H40: 1 | I40: 560 | J40: No | K40: Unknown | L40: =Assumptions!B3 | M40: =E40-L40 | N40: =-PMT(Assumptions!B2/12,Assumptions!B4*12,M40) | O40: =E40*Assumptions!B5/12 | P40: =Assumptions!B6 | Q40: =Assumptions!B7+Assumptions!B8 | R40: =N40+F40+O40+P40+Q40 | S40: 0 | T40: =R40-S40*MAX(IFERROR(G40-1,0),0) | U40: 0.7 | V40: 12.8 | W40: 12.5 | X40: 2.1 | Y40: Yellow
...
