Workbook

Sheet Assumptions
A1: Assumption | B1: Value
A2: Interest Rate | B2: 0.065
A3: Down Payment % | B3: 0.2
A4: Loan Term Years | B4: 30
A5: Property Tax Rate | B5: 0.012
A6: Insurance $/mo | B6: 150
A7: Utilities $/mo | B7: 250
A8: Internet $/mo | B8: 60

Sheet Listings
A1: Address | B1: Town | C1: Zillow URL | D1: Price | E1: HOA/mo | F1: Beds/Baths | G1: Sq Ft | H1: In-Unit Laundry | I1: Parking | J1: Down Payment $ | K1: Loan Amount | L1: Monthly Mortgage | M1: Property Tax/mo | N1: Insurance/mo | O1: Utilities+Internet | P1: Total Monthly Cost | Q1: Area Rental Price (Roommate) | R1: Net Monthly Cost | S1: Drive to MBTA (min) | T1: Drive to Seaport (min) | U1: Drive to Google (min) | V1: Rating Score | W1: Rating
A2: 0 Gordon Rd, Medford, MA 02155 | B2: Medford | C2: https://www.zillow.com/homedetails/0-Gordon-Rd-Medford-MA-02155/2100126227_zpid/ | D2: 369000 | E2: 0 | F2: ?bd/?ba | G2: 9732 | H2: No | I2: None listed | J2: =D2*Assumptions!B3 | K2: =D2-J2 | L2: =-PMT(Assumptions!B2/12,Assumptions!B4*12,K2) | M2: =D2*Assumptions!B5/12 | N2: =Assumptions!B6 | O2: =Assumptions!B7+Assumptions!B8 | P2: =L2+E2+M2+N2+O2 | Q2: 1790 | R2: =P2-Q2 | S2: 5 | T2: 12.3 | U2: 12.6 | V2: 2.8 | W2: Green
A3: 1-Bedroom Plan, 20 Whitney | B3: Quincy | C3: https://www.zillow.com/community/20-whitney/456675877_zpid/ | D3: 399000 | E3: 0 | F3: 1bd/1.0ba | G3: 500 | H3: No | I3: Off Street | J3: =D3*Assumptions!B3 | K3: =D3-J3 | L3: =-PMT(Assumptions!B2/12,Assumptions!B4*12,K3) | M3: =D3*Assumptions!B5/12 | N3: =Assumptions!B6 | O3: =Assumptions!B7+Assumptions!B8 | P3: =L3+E3+M3+N3+O3 | Q3: 1315 | R3: =P3-Q3 | V3: 2.45 | W3: Green
A4: 975 Washington St, Newtonville, MA 02460 | B4: Newton | C4: https://www.zillow.com/homedetails/975-Washington-St-Newtonville-MA-02460/459474131_zpid/ | D4: 1 | E4: 0 | F4: ?bd/?ba | G4: 34210 | H4: No | I4: None listed | J4: =D4*Assumptions!B3 | K4: =D4-J4 | L4: =-PMT(Assumptions!B2/12,Assumptions!B4*12,K4) | M4: =D4*Assumptions!B5/12 | N4: =Assumptions!B6 | O4: =Assumptions!B7+Assumptions!B8 | P4: =L4+E4+M4+N4+O4 | Q4: 2200 | R4: =P4-Q4 | S4: 5.8 | T4: 16.2 | U4: 16.7 | V4: 2.45 | W4: Green
A5: 133 Warren St APT 3, Watertown, MA 02472 | B5: Watertown | C5: https://www.zillow.com/homedetails/133-Warren-St-APT-3-Watertown-MA-02472/56370749_zpid/ | D5: 375000 | E5: 350 | F5: 2bd/1.0ba | G5: 600 | H5: No | I5: Off Street, Assigned, Deeded | J5: =D5*Assumptions!B3 | K5: =D5-J5 | L5: =-PMT(Assumptions!B2/12,Assumptions!B4*12,K5) | M5: =D5*Assumptions!B5/12 | N5: =Assumptions!B6 | O5: =Assumptions!B7+Assumptions!B8 | P5: =L5+E5+M5+N5+O5 | Q5: 1224 | R5: =P5-Q5 | V5: 2.45 | W5: Green
A6: 194 Lexington St APT 1, Watertown, MA 02472 | B6: Watertown | C6: https://www.zillow.com/homedetails/194-Lexington-St-APT-1-Watertown-MA-02472/56370715_zpid/ | D6: 375000 | E6: 350 | F6: 2bd/1.0ba | G6: 600 | H6: No | I6: Off Street, Assigned, Driveway | J6: =D6*Assumptions!B3 | K6: =D6-J6 | L6: =-PMT(Assumptions!B2/12,Assumptions!B4*12,K6) | M6: =D6*Assumptions!B5/12 | N6: =Assumptions!B6 | O6: =Assumptions!B7+Assumptions!B8 | P6: =L6+E6+M6+N6+O6 | Q6: 1224 | R6: =P6-Q6 | V6: 2.45 | W6: Green
A7: 151 Tremont St #U-508, Boston, MA 02111 | B7: Cambridge | C7: https://www.zillow.com/homedetails/151-Tremont-St-U-508-Boston-MA-02111/431633767_zpid/ | D7: 56500 | E7: 192 | F7: ?bd/?ba | G7: 10018 | H7: No | I7: None listed | J7: =D7*Assumptions!B3 | K7: =D7-J7 | L7: =-PMT(Assumptions!B2/12,Assumptions!B4*12,K7) | M7: =D7*Assumptions!B5/12 | N7: =Assumptions!B6 | O7: =Assumptions!B7+Assumptions!B8 | P7: =L7+E7+M7+N7+O7 | Q7: 3514 | R7: =P7-Q7 | V7: 2.45 | W7: Green
A8: 133 Commander Shea Blvd APT 502, Quincy, MA 02171 | B8: Quincy | C8: https://www.zillow.com/homedetails/133-Commander-Shea-Blvd-APT-502-Quincy-MA-02171/56602111_zpid/ | D8: 349900 | E8: 0 | F8: 1bd/1.0ba | G8: 644 | H8: No | I8: Unknown | J8: =D8*Assumptions!B3 | K8: =D8-J8 | L8: =-PMT(Assumptions!B2/12,Assumptions!B4*12,K8) | M8: =D8*Assumptions!B5/12 | N8: =Assumptions!B6 | O8: =Assumptions!B7+Assumptions!B8 | P8: =L8+E8+M8+N8+O8 | Q8: 1800 | R8: =P8-Q8 | V8: 2.4 | W8: Green
A9: 1025 Hancock St Unit 2K, Quincy, MA 02169 | B9: Quincy | C9: https://www.zillow.com/homedetails/1025-Hancock-St-UNIT-2K-Quincy-MA-02169/66655529_zpid/ | D9: 264000 | E9: 0 | F9: ?bd/1.0ba | G9: 445 | H9: No | I9: Unknown | J9: =D9*Assumptions!B3 | K9: =D9-J9 | L9: =-PMT(Assumptions!B2/12,Assumptions!B4*12,K9) | M9: =D9*Assumptions!B5/12 | N9: =Assumptions!B6 | O9: =Assumptions!B7+Assumptions!B8 | P9: =L9+E9+M9+N9+O9 | Q9: 1800 | R9: =P9-Q9 | V9: 2.4 | W9: Green
A10: 88 Gordon St APT 304, Brighton, MA 02135 | B10: Brighton | C10: https://www.zillow.com/homedetails/88-Gordon-St-APT-304-Brighton-MA-02135/59162680_zpid/ | D10: 399000 | E10: 0 | F10: 1bd/1.0ba | G10: 533 | H10: No | I10: Unknown | J10: =D10*Assumptions!B3 | K10: =D10-J10 | L10: =-PMT(Assumptions!B2/12,Assumptions!B4*12,K10) | M10: =D10*Assumptions!B5/12 | N10: =Assumptions!B6 | O10: =Assumptions!B7+Assumptions!B8 | P10: =L10+E10+M10+N10+O10 | Q10: 2000 | R10: =P10-Q10 | V10: 2.4 | W10: Green
A11: 26 Chiswick Rd APT 6, Brighton, MA 02135 | B11: Brighton | C11: https://www.zillow.com/homedetails/26-Chiswick-Rd-APT-6-Brighton-MA-02135/59094013_zpid/ | D11: 368000 | E11: 0 | F11: 1bd/1.0ba | G11: 470 | H11: No | I11: Unknown | J11: =D11*Assumptions!B3 | K11: =D11-J11 | L11: =-PMT(Assumptions!B2/12,Assumptions!B4*12,K11) | M11: =D11*Assumptions!B5/12 | N11: =Assumptions!B6 | O11: =Assumptions!B7+Assumptions!B8 | P11: =L11+E11+M11+N11+O11 | Q11: 2000 | R11: =P11-Q11 | V11: 2.4 | W11: Green
A12: 10 Skyline Dr APT 5, Braintree, MA 02184 | B12: Quincy | C12: https://www.zillow.com/homedetails/10-Skyline-Dr-APT-5-Braintree-MA-02184/184109022_zpid/ | D12: 359000 | E12: 465 | F12: 2bd/1.0ba | G12: 850 | H12: No | I12: Deeded, Assigned | J12: =D12*Assumptions!B3 | K12: =D12-J12 | L12: =-PMT(Assumptions!B2/12,Assumptions!B4*12,K12) | M12: =D12*Assumptions!B5/12 | N12: =Assumptions!B6 | O12: =Assumptions!B7+Assumptions!B8 | P12: =L12+E12+M12+N12+O12 | Q12: 1140 | R12: =P12-Q12 | V12: 2.35 | W12: Green
A13: 66 Bryon Rd APT 2, Chestnut Hill, MA 02467 | B13: Newton | C13: https://www.zillow.com/homedetails/66-Bryon-Rd-APT-2-Chestnut-Hill-MA-02467/2128070393_zpid/ | D13: 385000 | E13: 422 | F13: 2bd/1.0ba | G13: 780 | H13: No | I13: Deeded, Paved | J13: =D13*Assumptions!B3 | K13: =D13-J13 | L13: =-PMT(Assumptions!B2/12,Assumptions!B4*12,K13) | M13: =D13*Assumptions!B5/12 | N13: =Assumptions!B6 | O13: =Assumptions!B7+Assumptions!B8 | P13: =L13+E13+M13+N13+O13 | Q13: 1386 | R13: =P13-Q13 | V13: 2.35 | W13: Green
A14: 60 Bryon Rd APT 1, Chestnut Hill, MA 02467 | B14: Newton | C14: https://www.zillow.com/homedetails/60-Bryon-Rd-APT-1-Chestnut-Hill-MA-02467/2107598505_zpid/ | D14: 348899 | E14: 358 | F14: 2bd/1.0ba | G14: 786 | H14: No | I14: None listed | J14: =D14*Assumptions!B3 | K14: =D14-J14 | L14: =-PMT(Assumptions!B2/12,Assumptions!B4*12,K14) | M14: =D14*Assumptions!B5/12 | N14: =Assumptions!B6 | O14: =Assumptions!B7+Assumptions!B8 | P14: =L14+E14+M14+N14+O14 | Q14: 1334 | R14: =P14-Q14 | V14: 2.35 | W14: Green
A15: 38 Carey Ave APT 3, Watertown, MA 02472 | B15: Watertown | C15: https://www.zillow.com/homedetails/38-Carey-Ave-APT-3-Watertown-MA-02472/56370676_zpid/ | D15: 374899 | E15: 350 | F15: 2bd/1.0ba | G15: 600 | H15: No | I15: None listed | J15: =D15*Assumptions!B3 | K15: =D15-J15 | L15: =-PMT(Assumptions!B2/12,Assumptions!B4*12,K15) | M15: =D15*Assumptions!B5/12 | N15: =Assumptions!B6 | O15: =Assumptions!B7+Assumptions!B8 | P15: =L15+E15+M15+N15+O15 | Q15: 1135 | R15: =P15-Q15 | V15: 2.35 | W15: Green
A16: 1641 Commonwealth Ave APT 16, Brighton, MA 02135 | B16: Brighton | C16: https://www.zillow.com/homedetails/1641-Commonwealth-Ave-APT-16-Brighton-MA-02135/59089337_zpid/ | D16: 349000 | E16: 399 | F16: 1bd/1.0ba | G16: 407 | H16: No | I16: On Street | J16: =D16*Assumptions!B3 | K16: =D16-J16 | L16: =-PMT(Assumptions!B2/12,Assumptions!B4*12,K16) | M16: =D16*Assumptions!B5/12 | N16: =Assumptions!B6 | O16: =Assumptions!B7+Assumptions!B8 | P16: =L16+E16+M16+N16+O16 | Q16: 1237 | R16: =P16-Q16 | V16: 2.35 | W16: Green
A17: 354 Market St APT 9, Brighton, MA 02135 | B17: Brighton | C17: https://www.zillow.com/homedetails/354-Market-St-APT-9-Brighton-MA-02135/59093859_zpid/ | D17: 374900 | E17: 311 | F17: 1bd/1.0ba | G17: 590 | H17: No | I17: Off Street, Assigned, Paved | J17: =D17*Assumptions!B3 | K17: =D17-J17 | L17: =-PMT(Assumptions!B2/12,Assumptions!B4*12,K17) | M17: =D17*Assumptions!B5/12 | N17: =Assumptions!B6 | O17: =Assumptions!B7+Assumptions!B8 | P17: =L17+E17+M17+N17+O17 | Q17: 1362 | R17: =P17-Q17 | V17: 2.35 | W17: Green
A18: 5 Braemore Rd APT 10, Brighton, MA 02135 | B18: Brighton | C18: https://www.zillow.com/homedetails/5-Braemore-Rd-APT-10-Brighton-MA-02135/59213457_zpid/ | D18: 315000 | E18: 352 | F18: 1bd/1.0ba | G18: 385 | H18: No | I18: On Street | J18: =D18*Assumptions!B3 | K18: =D18-J18 | L18: =-PMT(Assumptions!B2/12,Assumptions!B4*12,K18) | M18: =D18*Assumptions!B5/12 | N18: =Assumptions!B6 | O18: =Assumptions!B7+Assumptions!B8 | P18: =L18+E18+M18+N18+O18 | Q18: 1344 | R18: =P18-Q18 | V18: 2.35 | W18: Green
A19: 32 Almont St #1, Medford, MA 02155 | B19: Medford | C19: https://www.zillow.com/homedetails/32-Almont-St-1-Medford-MA-02155/71661241_zpid/ | D19: 330000 | E19: 241 | F19: 1bd/1.0ba | G19: 528 | H19: No | I19: Open | J19: =D19*Assumptions!B3 | K19: =D19-J19 | L19: =-PMT(Assumptions!B2/12,Assumptions!B4*12,K19) | M19: =D19*Assumptions!B5/12 | N19: =Assumptions!B6 | O19: =Assumptions!B7+Assumptions!B8 | P19: =L19+E19+M19+N19+O19 | Q19: 1284 | R19: =P19-Q19 | V19: 2.35 | W19: Green
A20: 212 Quincy Shore Dr #A, Quincy, MA 02171 | B20: Quincy | C20: https://www.zillow.com/homedetails/212-Quincy-Shore-Dr-A-Quincy-MA-02171/458571840_zpid/ | D20: 499900 | E20: 0 | F20: 2bd/1.0ba | G20: 864 | H20: No | I20: Unknown | J20: =D20*Assumptions!B3 | K20: =D20-J20 | L20: =-PMT(Assumptions!B2/12,Assumptions!B4*12,K20) | M20: =D20*Assumptions!B5/12 | N20: =Assumptions!B6 | O20: =Assumptions!B7+Assumptions!B8 | P20: =L20+E20+M20+N20+O20 | Q20: 1800 | R20: =P20-Q20 | V20: 2.3 | W20: Green
A21: 200 Falls Blvd Unit B305, Quincy, MA 02169 | B21: Quincy | C21: https://www.zillow.com/homedetails/200-Falls-Blvd-UNIT-B305-Quincy-MA-02169/56590577_zpid/ | D21: 463000 | E21: 0 | F21: 2bd/2.0ba | G21: 980 | H21: No | I21: Unknown | J21: =D21*Assumptions!B3 | K21: =D21-J21 | L21: =-PMT(Assumptions!B2/12,Assumptions!B4*12,K21) | M21: =D21*Assumptions!B5/12 | N21: =Assumptions!B6 | O21: =Assumptions!B7+Assumptions!B8 | P21: =L21+E21+M21+N21+O21 | Q21: 1800 | R21: =P21-Q21 | V21: 2.3 | W21: Green
A22: 16 Winter St APT 26C, Waltham, MA 02451 | B22: Waltham | C22: https://www.zillow.com/homedetails/16-Winter-St-APT-26C-Waltham-MA-02451/56360152_zpid/ | D22: 425000 | E22: 0 | F22: 2bd/2.0ba | G22: 1000 | H22: No | I22: Unknown | J22: =D22*Assumptions!B3 | K22: =D22-J22 | L22: =-PMT(Assumptions!B2/12,Assumptions!B4*12,K22) | M22: =D22*Assumptions!B5/12 | N22: =Assumptions!B6 | O22: =Assumptions!B7+Assumptions!B8 | P22: =L22+E22+M22+N22+O22 | Q22: 1900 | R22: =P22-Q22 | V22: 2.3 | W22: Green
A23: 164 Galen St APT 65, Watertown, MA 02472 | B23: Newton | C23: https://www.zillow.com/homedetails/164-Galen-St-APT-65-Watertown-MA-02472/56367887_zpid/ | D23: 409000 | E23: 0 | F23: 2bd/1.0ba | G23: 950 | H23: No | I23: Unknown | J23: =D23*Assumptions!B3 | K23: =D23-J23 | L23: =-PMT(Assumptions!B2/12,Assumptions!B4*12,K23) | M23: =D23*Assumptions!B5/12 | N23: =Assumptions!B6 | O23: =Assumptions!B7+Assumptions!B8 | P23: =L23+E23+M23+N23+O23 | Q23: 2200 | R23: =P23-Q23 | V23: 2.3 | W23: Green
A24: 45 Gordon St APT 4, Allston, MA 02134 | B24: Brighton | C24: https://www.zillow.com/homedetails/45-Gordon-St-APT-4-Allston-MA-02134/59088776_zpid/ | D24: 489000 | E24: 0 | F24: 2bd/1.0ba | G24: 675 | H24: No | I24: Unknown | J24: =D24*Assumptions!B3 | K24: =D24-J24 | L24: =-PMT(Assumptions!B2/12,Assumptions!B4*12,K24) | M24: =D24*Assumptions!B5/12 | N24: =Assumptions!B6 | O24: =Assumptions!B7+Assumptions!B8 | P24: =L24+E24+M24+N24+O24 | Q24: 2000 | R24: =P24-Q24 | V24: 2.3 | W24: Green
A25: 59 Brighton Ave APT A, Allston, MA 02134 | B25: Allston | C25: https://www.zillow.com/homedetails/59-Brighton-Ave-APT-A-Allston-MA-02134/59087457_zpid/ | D25: 479900 | E25: 0 | F25: 2bd/1.0ba | G25: 670 | H25: No | I25: Unknown | J25: =D25*Assumptions!B3 | K25: =D25-J25 | L25: =-PMT(Assumptions!B2/12,Assumptions!B4*12,K25) | M25: =D25*Assumptions!B5/12 | N25: =Assumptions!B6 | O25: =Assumptions!B7+Assumptions!B8 | P25: =L25+E25+M25+N25+O25 | Q25: 1900 | R25: =P25-Q25 | V25: 2.3 | W25: Green
A26: 195 Thomas Burgin Pkwy Unit 212, Quincy, MA 02169 | B26: Quincy | C26: https://www.zillow.com/homedetails/195-Thomas-Burgin-Pkwy-UNIT-212-Quincy-MA-02169/56587202_zpid/ | D26: 249900 | E26: 345 | F26: ?bd/1.0ba | G26: 355 | H26: No | I26: None listed | J26: =D26*Assumptions!B3 | K26: =D26-J26 | L26: =-PMT(Assumptions!B2/12,Assumptions!B4*12,K26) | M26: =D26*Assumptions!B5/12 | N26: =Assumptions!B6 | O26: =Assumptions!B7+Assumptions!B8 | P26: =L26+E26+M26+N26+O26 | Q26: 988 | R26: =P26-Q26 | V26: 2.25 | W26: Yellow
A27: 14-16 Cottage Pl, West Newton, MA 02465 | B27: Newton | C27: https://www.zillow.com/homedetails/14-16-Cottage-Pl-West-Newton-MA-02465/2062072214_zpid/ | D27: 549950 | E27: 0 | F27: 2bd/1.0ba | G27: 874 | H27: No | I27: Off Street | J27: =D27*Assumptions!B3 | K27: =D27-J27 | L27: =-PMT(Assumptions!B2/12,Assumptions!B4*12,K27) | M27: =D27*Assumptions!B5/12 | N27: =Assumptions!B6 | O27: =Assumptions!B7+Assumptions!B8 | P27: =L27+E27+M27+N27+O27 | Q27: 2134 | R27: =P27-Q27 | S27: 4.8 | T27: 17.4 | U27: 17.9 | V27: 2.25 | W27: Yellow
A28: 10 Hammond Pond Pkwy APT 606, Newton, MA 02467 | B28: Newton | C28: https://www.zillow.com/homedetails/10-Hammond-Pond-Pkwy-APT-606-Newton-MA-02467/56321646_zpid/ | D28: 350000 | E28: 459 | F28: ?bd/1.0ba | G28: 508 | H28: No | I28: Carport, Storage, Deeded | J28: =D28*Assumptions!B3 | K28: =D28-J28 | L28: =-PMT(Assumptions!B2/12,Assumptions!B4*12,K28) | M28: =D28*Assumptions!B5/12 | N28: =Assumptions!B6 | O28: =Assumptions!B7+Assumptions!B8 | P28: =L28+E28+M28+N28+O28 | Q28: 1398 | R28: =P28-Q28 | V28: 2.25 | W28: Yellow
A29: 1151 Walnut St #207, Newton Highlands, MA 02461 | B29: Newton | C29: https://www.zillow.com/homedetails/1151-Walnut-St-207-Newton-Highlands-MA-02461/457256057_zpid/ | D29: 450000 | E29: 165 | F29: ?bd/1.0ba | G29: 455 | H29: No | I29: Under, Assigned, Off Street | J29: =D29*Assumptions!B3 | K29: =D29-J29 | L29: =-PMT(Assumptions!B2/12,Assumptions!B4*12,K29) | M29: =D29*Assumptions!B5/12 | N29: =Assumptions!B6 | O29: =Assumptions!B7+Assumptions!B8 | P29: =L29+E29+M29+N29+O29 | Q29: 2200 | R29: =P29-Q29 | V29: 2.25 | W29: Yellow
A30: 1151 Walnut St #304, Newton Highlands, MA 02461 | B30: Newton | C30: https://www.zillow.com/homedetails/1151-Walnut-St-304-Newton-Highlands-MA-02461/459913262_zpid/ | D30: 495000 | E30: 197 | F30: ?bd/1.0ba | G30: 511 | H30: No | I30: Under, Assigned, Off Street | J30: =D30*Assumptions!B3 | K30: =D30-J30 | L30: =-PMT(Assumptions!B2/12,Assumptions!B4*12,K30) | M30: =D30*Assumptions!B5/12 | N30: =Assumptions!B6 | O30: =Assumptions!B7+Assumptions!B8 | P30: =L30+E30+M30+N30+O30 | Q30: 2200 | R30: =P30-Q30 | V30: 2.25 | W30: Yellow
A31: 88 Gordon St APT 305, Brighton, MA 02135 | B31: Brighton | C31: https://www.zillow.com/homedetails/88-Gordon-St-APT-305-Brighton-MA-02135/59091169_zpid/ | D31: 299000 | E31: 292 | F31: 1bd/1.0ba | G31: 283 | H31: No | I31: None listed | J31: =D31*Assumptions!B3 | K31: =D31-J31 | L31: =-PMT(Assumptions!B2/12,Assumptions!B4*12,K31) | M31: =D31*Assumptions!B5/12 | N31: =Assumptions!B6 | O31: =Assumptions!B7+Assumptions!B8 | P31: =L31+E31+M31+N31+O31 | Q31: 1655 | R31: =P31-Q31 | V31: 2.25 | W31: Yellow
A32: 198 Allston St #3, Allston, MA 02134 | B32: Brighton | C32: https://www.zillow.com/homedetails/198-Allston-St-3-Allston-MA-02134/440796556_zpid/ | D32: 270000 | E32: 295 | F32: 1bd/1.0ba | G32: 318 | H32: No | I32: None listed | J32: =D32*Assumptions!B3 | K32: =D32-J32 | L32: =-PMT(Assumptions!B2/12,Assumptions!B4*12,K32) | M32: =D32*Assumptions!B5/12 | N32: =Assumptions!B6 | O32: =Assumptions!B7+Assumptions!B8 | P32: =L32+E32+M32+N32+O32 | Q32: 2000 | R32: =P32-Q32 | V32: 2.25 | W32: Yellow
A33: 15 Commonwealth Ct APT 10, Brighton, MA 02135 | B33: Brighton | C33: https://www.zillow.com/homedetails/15-Commonwealth-Ct-APT-10-Brighton-MA-02135/59091656_zpid/ | D33: 379900 | E33: 500 | F33: 1bd/1.0ba | G33: 688 | H33: No | I33: Off Street, Deeded | J33: =D33*Assumptions!B3 | K33: =D33-J33 | L33: =-PMT(Assumptions!B2/12,Assumptions!B4*12,K33) | M33: =D33*Assumptions!B5/12 | N33: =Assumptions!B6 | O33: =Assumptions!B7+Assumptions!B8 | P33: =L33+E33+M33+N33+O33 | Q33: 1601 | R33: =P33-Q33 | V33: 2.25 | W33: Yellow
A34: 1564 Commonwealth Ave APT 3, Brighton, MA 02135 | B34: Brighton | C34: https://www.zillow.com/homedetails/1564-Commonwealth-Ave-APT-3-Brighton-MA-02135/59092148_zpid/ | D34: 315000 | E34: 370 | F34: ?bd/1.0ba | G34: 306 | H34: No | I34: None listed | J34: =D34*Assumptions!B3 | K34: =D34-J34 | L34: =-PMT(Assumptions!B2/12,Assumptions!B4*12,K34) | M34: =D34*Assumptions!B5/12 | N34: =Assumptions!B6 | O34: =Assumptions!B7+Assumptions!B8 | P34: =L34+E34+M34+N34+O34 | Q34: 1144 | R34: =P34-Q34 | V34: 2.25 | W34: Yellow
A35: 77 Pond Avenue #1103, Brookline, MA 02445 | B35: Brookline | C35: https://www.zillow.com/homedetails/77-Pond-Ave-APT-1103-Brookline-MA-02445/56571183_zpid/ | D35: 489900 | E35: 0 | F35: 1bd/1.0ba | G35: 860 | H35: No | I35: Unknown | J35: =D35*Assumptions!B3 | K35: =D35-J35 | L35: =-PMT(Assumptions!B2/12,Assumptions!B4*12,K35) | M35: =D35*Assumptions!B5/12 | N35: =Assumptions!B6 | O35: =Assumptions!B7+Assumptions!B8 | P35: =L35+E35+M35+N35+O35 | Q35: 2400 | R35: =P35-Q35 | V35: 2.25 | W35: Yellow
A36: 217-221 Highland Ave Unit 1, Malden, MA 02148 | B36: Medford | C36: https://www.zillow.com/homedetails/217-221-Highland-Ave-UNIT-1-Malden-MA-02148/459672098_zpid/ | D36: 499900 | E36: 390 | F36: 3bd/2.0ba | G36: 1183 | H36: No | I36: On Street, Assigned, Paved, Exclusive Parking | J36: =D36*Assumptions!B3 | K36: =D36-J36 | L36: =-PMT(Assumptions!B2/12,Assumptions!B4*12,K36) | M36: =D36*Assumptions!B5/12 | N36: =Assumptions!B6 | O36: =Assumptions!B7+Assumptions!B8 | P36: =L36+E36+M36+N36+O36 | Q36: 1900 | R36: =P36-Q36 | V36: 2.25 | W36: Yellow
A37: 24 South St APT 38, Medford, MA 02155 | B37: Medford | C37: https://www.zillow.com/homedetails/24-South-St-APT-38-Medford-MA-02155/56281218_zpid/ | D37: 449900 | E37: 0 | F37: 1bd/2.0ba | G37: 757 | H37: No | I37: Unknown | J37: =D37*Assumptions!B3 | K37: =D37-J37 | L37: =-PMT(Assumptions!B2/12,Assumptions!B4*12,K37) | M37: =D37*Assumptions!B5/12 | N37: =Assumptions!B6 | O37: =Assumptions!B7+Assumptions!B8 | P37: =L37+E37+M37+N37+O37 | Q37: 1900 | R37: =P37-Q37 | V37: 2.25 | W37: Yellow
A38: 80 Main St APT 4, Malden, MA 02148 | B38: Medford | C38: https://www.zillow.com/homedetails/80-Main-St-APT-4-Malden-MA-02148/56268453_zpid/ | D38: 335000 | E38: 430 | F38: 1bd/1.0ba | G38: 578 | H38: No | I38: Off Street | J38: =D38*Assumptions!B3 | K38: =D38-J38 | L38: =-PMT(Assumptions!B2/12,Assumptions!B4*12,K38) | M38: =D38*Assumptions!B5/12 | N38: =Assumptions!B6 | O38: =Assumptions!B7+Assumptions!B8 | P38: =L38+E38+M38+N38+O38 | Q38: 1293 | R38: =P38-Q38 | V38: 2.25 | W38: Yellow
A39: 80 Main St APT 9, Malden, MA 02148 | B39: Medford | C39: https://www.zillow.com/homedetails/80-Main-St-APT-9-Malden-MA-02148/56268458_zpid/ | D39: 359900 | E39: 426 | F39: 1bd/1.0ba | G39: 605 | H39: No | I39: Off Street | J39: =D39*Assumptions!B3 | K39: =D39-J39 | L39: =-PMT(Assumptions!B2/12,Assumptions!B4*12,K39) | M39: =D39*Assumptions!B5/12 | N39: =Assumptions!B6 | O39: =Assumptions!B7+Assumptions!B8 | P39: =L39+E39+M39+N39+O39 | Q39: 1276 | R39: =P39-Q39 | V39: 2.25 | W39: Yellow
A40: 100 Washington St APT 3, Brighton, MA 02135 | B40: Brighton | C40: https://www.zillow.com/homedetails/100-Washington-St-APT-3-Brighton-MA-02135/59092287_zpid/ | D40: 449000 | E40: 0 | F40: 1bd/1.0ba | G40: 682 | H40: No | I40: Unknown | J40: =D40*Assumptions!B3 | K40: =D40-J40 | L40: =-PMT(Assumptions!B2/12,Assumptions!B4*12,K40) | M40: =D40*Assumptions!B5/12 | N40: =Assumptions!B6 | O40: =Assumptions!B7+Assumptions!B8 | P40: =L40+E40+M40+N40+O40 | Q40: 2000 | R40: =P40-Q40 | V40: 2.2 | W40: Yellow
...
